Workbook

Sheet Sheet2
A3: Count of tranzakció Egyedi azonosító | B3: Column Labels
A4: Row Labels | B4: K | C4: T | D4: Grand Total
A5: ATV/1/2025 | B5: 1 | C5: 1 | D5: 2
A6: ATV/2/2025 | B6: 1 | C6: 1 | D6: 2
A7: FIZ/DIJ/1/2025 | B7: 2 | C7: 2 | D7: 4
A8: FIZ/DIJ/10/2025 | B8: 4 | C8: 3 | D8: 7
A9: FIZ/DIJ/11/2025 | B9: 4 | C9: 3 | D9: 7
A10: FIZ/DIJ/12/2025 | B10: 2 | C10: 2 | D10: 4
A11: FIZ/DIJ/13/2025 | B11: 4 | C11: 3 | D11: 7
A12: FIZ/DIJ/13/2025/STORNO | B12: 4 | C12: 3 | D12: 7
A13: FIZ/DIJ/14/2025 | B13: 2 | C13: 2 | D13: 4
A14: FIZ/DIJ/15/2025 | B14: 2 | C14: 2 | D14: 4
A15: FIZ/DIJ/16/2025 | B15: 2 | C15: 2 | D15: 4
A16: FIZ/DIJ/17/2025 | B16: 2 | C16: 2 | D16: 4
... A123: Grand Total | B123: 162 | C123: 160 | D123: 322

Sheet journal entries
A1: Értéknap | B1: számla kód | C1: számla név | D1: Oldal | E1: Összeg | F1: tranzakció Egyedi azonosító
A2: 2025.11.05 | B2: 5306 | C2: =VLOOKUP(B2,számlarend!A:B,2,FALSE) -> Hatósági díjak | D2: T | E2: 40000 | F2: SZ/SZAL/4/2025
A3: 2025.11.05 | B3: 454 | C3: =VLOOKUP(B3,számlarend!A:B,2,FALSE) -> Szállítók | D3: K | E3: 40000 | F3: SZ/SZAL/4/2025
A4: 2025.10.31 | B4: 5302 | C4: =VLOOKUP(B4,számlarend!A:B,2,FALSE) -> Bank költségek | D4: T | E4: 792 | F4: NY/SZAL/45/2025
A5: 2025.10.31 | B5: 382 | C5: =VLOOKUP(B5,számlarend!A:B,2,FALSE) -> Folyószámla | D5: K | E5: 792 | F5: NY/SZAL/45/2025
A6: 2025.10.31 | B6: 5302 | C6: =VLOOKUP(B6,számlarend!A:B,2,FALSE) -> Bank költségek | D6: T | E6: 486 | F6: NY/SZAL/46/2025
A7: 2025.10.31 | B7: 382 | C7: =VLOOKUP(B7,számlarend!A:B,2,FALSE) -> Folyószámla | D7: K | E7: 486 | F7: NY/SZAL/46/2025
A8: 2025.10.23 | B8: 3831 | C8: =VLOOKUP(B8,számlarend!A:B,2,FALSE) -> Pál homály pénztár zsebe | D8: T | E8: 149736 | F8: NY/VEV/11/2025
A9: 2025.10.23 | B9: 711 | C9: =VLOOKUP(B9,számlarend!A:B,2,FALSE) -> Föld alapú támogatások | D9: K | E9: 149736 | F9: NY/VEV/11/2025
A10: 2025.10.20 | B10: 5306 | C10: =VLOOKUP(B10,számlarend!A:B,2,FALSE) -> Hatósági díjak | D10: T | E10: 40000 | F10: FIZ/SZAL/3/2025
A11: 2025.10.20 | B11: 454 | C11: =VLOOKUP(B11,számlarend!A:B,2,FALSE) -> Szállítók | D11: T | E11: 40000 | F11: FIZ/SZAL/3/2025
A12: 2025.10.20 | B12: 382 | C12: =VLOOKUP(B12,számlarend!A:B,2,FALSE) -> Folyószámla | D12: K | E12: 40000 | F12: FIZ/SZAL/3/2025
A13: 2025.10.20 | B13: 5306 | C13: =VLOOKUP(B13,számlarend!A:B,2,FALSE) -> Hatósági díjak | D13: K | E13: 40000 | F13: FIZ/SZAL/3/2025
... A323: 2024.12.10 | B323: 335 | C323: =VLOOKUP(B323,számlarend!A:B,2,FALSE) -> Rendkivüli befizetés előírás | D323: K | E323: -60000 | F323: FIZ/DIJ/13/2025/STORNO

Sheet számlák
A1: Azonosító | B1: Akció gombok | C1: Partner | D1: Számla kelte | E1: Teljesítés ideje | F1: Fizetési határidő | G1: Összeg | H1: Kifizetetlen | I1: Kifizetés ideje | J1: Megjegyzések
A2: SZ/DIJ/1/2025 | C2: Valenczi Pál | D2: 2024.12.01 | E2: 2024.12.14 | F2: 2024.12.31 | G2: 500000 | H2: 0 | I2: 2024.12.11 | J2: -
A3: SZ/DIJ/10/2025 | C3: Balázs Erika | D3: 2025.01.16 | E3: 2025.01.16 | F3: 2025.01.24 | G3: 12500000 | H3: 0 | I3: 2025.02.25 | J3: -
A4: SZ/DIJ/11/2025 | C4: Valenczi Pál | D4: 2024.12.01 | E4: 2024.12.14 | F4: 2024.12.31 | G4: 172000 | H4: 0 | I4: 2024.12.11 | J4: -
A5: SZ/DIJ/12/2025 | C5: Róka Dániel | D5: 2024.12.01 | E5: 2024.12.14 | F5: 2024.12.31 | G5: 172000 | H5: 0 | I5: 2024.12.11 | J5: -
A6: SZ/DIJ/13/2025 | C6: Fejős Ildikó | D6: 2024.12.01 | E6: 2024.12.14 | F6: 2024.12.31 | G6: 172000 | H6: 0 | I6: 2024.12.11 | J6: -
A7: SZ/DIJ/14/2025 | C7: Balázs Erika | D7: 2024.12.01 | E7: 2024.12.14 | F7: 2024.12.31 | G7: 172000 | H7: 0 | I7: 2024.12.11 | J7: -
A8: SZ/DIJ/15/2025 | C8: Viczián László | D8: 2024.12.01 | E8: 2024.12.14 | F8: 2024.12.31 | G8: 60000 | H8: 60000 | I8: 2024.12.10 | J8: -
A9: SZ/DIJ/16/2025 | C9: Horváth Péter | D9: 2024.12.01 | E9: 2024.12.14 | F9: 2024.12.31 | G9: 172000 | H9: 0 | I9: 2024.12.11 | J9: -
A10: SZ/DIJ/2/2025 | C10: Róka Dániel | D10: 2024.12.01 | E10: 2024.12.14 | F10: 2024.12.31 | G10: 500000 | H10: 0 | I10: 2024.12.10 | J10: -
A11: SZ/DIJ/3/2025 | C11: Fejős Ildikó | D11: 2024.12.01 | E11: 2024.12.14 | F11: 2024.12.31 | G11: 500000 | H11: 0 | I11: 2024.12.11 | J11: -
A12: SZ/DIJ/4/2025 | C12: Balázs Erika | D12: 2024.12.01 | E12: 2024.12.14 | F12: 2024.12.31 | G12: 500000 | H12: 0 | I12: 2024.12.11 | J12: -
A13: SZ/DIJ/5/2025 | C13: Viczián László | D13: 2024.12.01 | E13: 2024.12.14 | F13: 2024.12.31 | G13: 500000 | H13: 500000 | I13: 2024.12.10 | J13: -
... A17: SZ/DIJ/9/2025 | C17: Fejős Ildikó | D17: 2025.01.16 | E17: 2025.01.16 | F17: 2025.01.24 | G17: 12500000 | H17: 0 | I17: 2025.02.21 | J17: -
A18: Azonosító | B18: Akció gombok | C18: Partner | D18: Számla kelte | E18: Teljesítés ideje | F18: Fizetési határidő | G18: Összeg | H18: Kifizetetlen | I18: Kifizetés ideje | J18: Megjegyzések
A19: SZ/SZAL/5/2025 | C19: NAV | D19: 2025.10.10 | E19: 2025.10.10 | F19: 2025.12.11 | G19: 68000 | H19: 0 | I19: 2025.10.20 | J19: -
A20: SZ/SZAL/4/2025 | C20: NAV | D20: 2025.11.05 | E20: 2025.11.05 | F20: 2025.12.05 | G20: 40000 | H20: 0 | I20: 2025.10.20 | J20: -
A21: SZ/SZAL/3/2025 | C21: Dr. Fodor Marianna | D21: 2025.05.27 | E21: 2025.05.27 | F21: 2025.06.11 | G21: 160000 | H21: 0 | I21: 2025.06.04 | J21: 2025-28
A22: SZ/SZAL/2/2025 | C22: Dr. Fodor Marianna | D22: 2025.03.12 | E22: 2025.03.12 | F22: 2025.03.27 | G22: 80000 | H22: 0 | I22: 2025.03.13 | J22: 2025-11
A23: Azonosító | B23: Akció gombok | C23: Partner | D23: Értéknap | E23: Összeg | F23: Beazonosítatlan | G23: Pénz számla | H23: Megjegyzések
A24: FIZ/SZAL/1/2025 | C24: Dr. Fodor Marianna | D24: 2025.03.13 | E24: 80000 | F24: 0 | G24: 382: Folyószámla | H24: -
A25: FIZ/SZAL/2/2025 | C25: Dr. Fodor Marianna | D25: 2025.06.04 | E25: 160000 | F25: 0 | G25: 382: Folyószámla | H25: -
A26: FIZ/SZAL/3/2025 | C26: NAV | D26: 2025.10.20 | E26: 40000 | F26: 0 | G26: 382: Folyószámla | H26: -
A27: FIZ/SZAL/4/2025 | C27: NAV | D27: 2025.10.20 | E27: 68000 | F27: 0 | G27: 382: Folyószámla | H27: -
A28: Azonosító | B28: Akció gombok | C28: Partner | D28: Értéknap | E28: Összeg | F28: Megjegyzések
A29: NY/SZAL/1/2025 | C29: K&H Bank | D29: 2024.12.23 | E29: 4500 | F29: -
A30: NY/SZAL/11/2025 | C30: K&H Bank | D30: 2025.02.28 | E30: 20000 | F30: -
A31: NY/SZAL/12/2025 | C31: K&H Bank | D31: 2025.02.28 | E31: 764 | F31: -
A32: NY/SZAL/13/2025 | C32: Földhivatal | D32: 2025.03.14 | E32: 21200 | F32: -
A33: NY/SZAL/14/2025 | C33: K&H Bank | D33: 2025.03.31 | E33: 764 | F33: -
A34: NY/SZAL/15/2025 | C34: K&H Bank | D34: 2025.03.31 | E34: 360 | F34: -
A35: NY/SZAL/16/2025 | C35: K&H Bank | D35: 2025.04.30 | E35: 792 | F35: -
A36: NY/SZAL/17/2025 | C36: Valenczi Pál | D36: 2025.04.28 | E36: 30001 | F36: -
A37: NY/SZAL/18/2025 | C37: Valenczi Pál | D37: 2025.05.12 | E37: 31693 | F37: -
A38: NY/SZAL/19/2025 | C38: Valenczi Pál | D38: 2025.05.16 | E38: 31504 | F38: -
A39: NY/SZAL/2/2025 | C39: K&H Bank | D39: 2024.12.31 | E39: 255 | F39: -
A40: NY/SZAL/20/2025 | C40: K&H Bank | D40: 2025.05.30 | E40: 792 | F40: -
... A53: NY/SZAL/32/2025 | C53: K&H Bank | D53: 2025.07.31 | E53: 12703 | F53: -
A54: Előző
A55: 1
...

Sheet tranzakciók
A1: Létrehozva | B1: Értéknap | C1: Azonosító | D1: Akció gombok | E1: Gazdasági esemény | F1: Összeg | G1: Tartozik | H1: Követel | I1: Megjegyzések
A2: 2025.01.16 10:56 | B2: 2024.12.14 | C2: SZ/DIJ/1/2025 | E2: Albetét előírás | F2: 500000 | G2: 0336: Tagbetét előírás A1: A1 | H2: 0956: Tagbetét befizetés | I2: -
A3: 2025.01.16 10:56 | B3: 2024.12.14 | C3: SZ/DIJ/2/2025 | E3: Albetét előírás | F3: 500000 | G3: 0336: Tagbetét előírás A2: A2 | H3: 0956: Tagbetét befizetés | I3: -
A4: 2025.01.16 10:56 | B4: 2024.12.14 | C4: SZ/DIJ/3/2025 | E4: Albetét előírás | F4: 500000 | G4: 0336: Tagbetét előírás A3: A3 | H4: 0956: Tagbetét befizetés | I4: -
A5: 2025.01.16 10:56 | B5: 2024.12.14 | C5: SZ/DIJ/4/2025 | E5: Albetét előírás | F5: 500000 | G5: 0336: Tagbetét előírás A4: A4 | H5: 0956: Tagbetét befizetés | I5: -
A6: 2025.01.16 10:56 | B6: 2024.12.14 | C6: SZ/DIJ/5/2025 | E6: Albetét előírás | F6: 500000 | G6: 0336: Tagbetét előírás A5: A5 | H6: 0956: Tagbetét befizetés | I6: -
A7: 2025.01.16 10:56 | B7: 2024.12.14 | C7: SZ/DIJ/6/2025 | E7: Albetét előírás | F7: 500000 | G7: 0336: Tagbetét előírás A6: A6 | H7: 0956: Tagbetét befizetés | I7: -
A8: 2025.01.16 11:03 | B8: 2025.01.16 | C8: SZ/DIJ/7/2025 | E8: Albetét előírás | F8: 12500000 | G8: 0333: Földvásárlási alap előírás A1: A1 | H8: 0953: Földvásárlási alap befizetés | I8: -
A9: 2025.01.16 11:03 | B9: 2025.01.16 | C9: SZ/DIJ/8/2025 | E9: Albetét előírás | F9: 12500000 | G9: 0333: Földvásárlási alap előírás A2: A2 | H9: 0953: Földvásárlási alap befizetés | I9: -
A10: 2025.01.16 11:03 | B10: 2025.01.16 | C10: SZ/DIJ/9/2025 | E10: Albetét előírás | F10: 12500000 | G10: 0333: Földvásárlási alap előírás A3: A3 | H10: 0953: Földvásárlási alap befizetés | I10: -
A11: 2025.01.16 11:03 | B11: 2025.01.16 | C11: SZ/DIJ/10/2025 | E11: Albetét előírás | F11: 12500000 | G11: 0333: Földvásárlási alap előírás A4: A4 | H11: 0953: Földvásárlási alap befizetés | I11: -
A12: 2025.01.16 12:28 | B12: 2024.12.23 | C12: ATV/1/2025 | E12: Átvezetés pénz számlák között | F12: 3000000 | G12: 382: Folyószámla | H12: 3811: Pál pénztár zsebe | I12: -
A13: 2025.01.16 12:29 | B13: 2024.12.23 | C13: NY/SZAL/1/2025 | E13: Kiadás elszámolás | F13: 4500 | G13: 5302: Bank költségek | H13: 382: Folyószámla | I13: -
... A107: 2025.11.05 15:51 | B107: 2025.10.20 | C107: FIZ/SZAL/4/2025 | E107: Szállító számla kifizetés | F107: 68000 | G107: Több számla | H107: Több számla | I107: -

Sheet számlarend
A1: Kód | B1: Elnevezés | C1: Számla típus | D1: Gyűjtő
A2: 0 | B2: Technikai Számlák | C2: Technikai | D2: 0
A3: 1 | B3: BEFEKTETETT ESZKÖZÖK | C3: Eszköz | D3: =IF(EXACT(A3,LEFT(A4,LEN(A3))),1,0) -> 1
A4: 12 | B4: INGATLANOK ÉS KAPCSOLÓDÓ VAGYONI ÉRTÉKŰ JOGOK | C4: Eszköz | D4: =IF(EXACT(A4,LEFT(A5,LEN(A4))),1,0) -> 1
A5: 121 | B5: Földterület | C5: tr | D5: =IF(EXACT(A5,LEFT(A6,LEN(A5))),1,0) -> 0
A6: 122 | B6: Telek | C6: Eszköz | D6: =IF(EXACT(A6,LEFT(A7,LEN(A6))),1,0) -> 0
A7: 123 | B7: Épület | C7: Eszköz | D7: =IF(EXACT(A7,LEFT(A8,LEN(A7))),1,0) -> 0
A8: 129 | B8: Ingatlanok homály érték növekedése | C8: Eszköz | D8: =IF(EXACT(A8,LEFT(A9,LEN(A8))),1,0) -> 0
A9: 13 | B9: Műszaki berendezések | C9: Eszköz | D9: =IF(EXACT(A9,LEFT(A10,LEN(A9))),1,0) -> 0
A10: 14 | B10: Egyéb berendezésekberendezések | C10: Eszköz | D10: =IF(EXACT(A10,LEFT(A11,LEN(A10))),1,0) -> 0
A11: 16 | B11: Beruházások | C11: Eszköz | D11: =IF(EXACT(A11,LEFT(A12,LEN(A11))),1,0) -> 0
A12: 18 | B12: Hitelviszonyt metestesítő értékpapírok | C12: Eszköz | D12: =IF(EXACT(A12,LEFT(A13,LEN(A12))),1,0) -> 0
A13: 19 | B13: TARTÓSAN ADOTT KÖLCSÖNÖK | C13: Eszköz | D13: =IF(EXACT(A13,LEFT(A14,LEN(A13))),1,0) -> 1
A14: 192 | B14: Tagoknak adott kölcsönök | C14: Eszköz | D14: =IF(EXACT(A14,LEFT(A15,LEN(A14))),1,0) -> 0
... A274: 99 | B274: Kerekítési nyereség-veszteség | C274: Bevétel | D274: =IF(EXACT(A274,LEFT(A275,LEN(A274))),1,0) -> 0

Sheet Strapi.trx
A1: date | B1: time | C1: desc | D1: trx_type | E1: curr_type | F1: related | G1: amount | H1: debit_account | I1: credit_account | J1: receipt
